<?xml version="1.0"?>
<!--
  AGV URDF模型 - 差分驱动机器人
  - 底盘：0.4m x 0.3m x 0.1m
  - 两个驱动轮 + 两个万向轮
  - 激光雷达（顶部）
  - Gazebo插件：差分驱动、激光雷达、IMU
-->
<robot name="agv">

  <!-- ==================== 颜色定义 ==================== -->
  <material name="red">
    <color rgba="0.8 0.2 0.2 1.0"/>
  </material>
  <material name="blue">
    <color rgba="0.2 0.2 0.8 1.0"/>
  </material>
  <material name="gray">
    <color rgba="0.5 0.5 0.5 1.0"/>
  </material>
  <material name="dark_gray">
    <color rgba="0.3 0.3 0.3 1.0"/>
  </material>
  <material name="white">
    <color rgba="0.9 0.9 0.9 1.0"/>
  </material>

  <!-- ==================== 底盘 ==================== -->
  <link name="base_link">
    <visual>
      <geometry>
        <box size="0.4 0.3 0.1"/>
      </geometry>
      <origin xyz="0 0 0.05"/>
      <material name="gray"/>
    </visual>
    <collision>
      <geometry>
        <box size="0.4 0.3 0.1"/>
      </geometry>
      <origin xyz="0 0 0.05"/>
    </collision>
    <inertial>
      <mass value="10.0"/>
      <inertia ixx="0.1" ixy="0" ixz="0" iyy="0.1" iyz="0" izz="0.1"/>
    </inertial>
  </link>

  <!-- ==================== 左驱动轮 ==================== -->
  <link name="left_wheel">
    <visual>
      <geometry>
        <cylinder radius="0.05" length="0.04"/>
      </geometry>
      <origin xyz="0 0 0" rpy="1.5708 0 0"/>
      <material name="dark_gray"/>
    </visual>
    <collision>
      <geometry>
        <cylinder radius="0.05" length="0.04"/>
      </geometry>
      <origin xyz="0 0 0" rpy="1.5708 0 0"/>
    </collision>
    <inertial>
      <mass value="0.5"/>
      <inertia ixx="0.001" ixy="0" ixz="0" iyy="0.001" iyz="0" izz="0.001"/>
    </inertial>
  </link>

  <joint name="left_wheel_joint" type="continuous">
    <parent link="base_link"/>
    <child link="left_wheel"/>
    <origin xyz="0 0.17 0.05"/>
    <axis xyz="0 1 0"/>
  </joint>

  <!-- ==================== 右驱动轮 ==================== -->
  <link name="right_wheel">
    <visual>
      <geometry>
        <cylinder radius="0.05" length="0.04"/>
      </geometry>
      <origin xyz="0 0 0" rpy="1.5708 0 0"/>
      <material name="dark_gray"/>
    </visual>
    <collision>
      <geometry>
        <cylinder radius="0.05" length="0.04"/>
      </geometry>
      <origin xyz="0 0 0" rpy="1.5708 0 0"/>
    </collision>
    <inertial>
      <mass value="0.5"/>
      <inertia ixx="0.001" ixy="0" ixz="0" iyy="0.001" iyz="0" izz="0.001"/>
    </inertial>
  </link>

  <joint name="right_wheel_joint" type="continuous">
    <parent link="base_link"/>
    <child link="right_wheel"/>
    <origin xyz="0 -0.17 0.05"/>
    <axis xyz="0 1 0"/>
  </joint>

  <!-- ==================== 前万向轮 ==================== -->
  <link name="front_caster">
    <visual>
      <geometry>
        <sphere radius="0.03"/>
      </geometry>
      <material name="dark_gray"/>
    </visual>
    <collision>
      <geometry>
        <sphere radius="0.03"/>
      </geometry>
    </collision>
    <inertial>
      <mass value="0.1"/>
      <inertia ixx="0.0001" ixy="0" ixz="0" iyy="0.0001" iyz="0" izz="0.0001"/>
    </inertial>
  </link>

  <joint name="front_caster_joint" type="fixed">
    <parent link="base_link"/>
    <child link="front_caster"/>
    <origin xyz="0.18 0 0.02"/>
  </joint>

  <!-- ==================== 后万向轮 ==================== -->
  <link name="rear_caster">
    <visual>
      <geometry>
        <sphere radius="0.03"/>
      </geometry>
      <material name="dark_gray"/>
    </visual>
    <collision>
      <geometry>
        <sphere radius="0.03"/>
      </geometry>
    </collision>
    <inertial>
      <mass value="0.1"/>
      <inertia ixx="0.0001" ixy="0" ixz="0" iyy="0.0001" iyz="0" izz="0.0001"/>
    </inertial>
  </link>

  <joint name="rear_caster_joint" type="fixed">
    <parent link="base_link"/>
    <child link="rear_caster"/>
    <origin xyz="-0.18 0 0.02"/>
  </joint>

  <!-- ==================== 货物平台 ==================== -->
  <link name="cargo_platform">
    <visual>
      <geometry>
        <box size="0.35 0.25 0.02"/>
      </geometry>
      <origin xyz="0 0 0.11"/>
      <material name="white"/>
    </visual>
    <collision>
      <geometry>
        <box size="0.35 0.25 0.02"/>
      </geometry>
      <origin xyz="0 0 0.11"/>
    </collision>
    <inertial>
      <mass value="1.0"/>
      <inertia ixx="0.01" ixy="0" ixz="0" iyy="0.01" iyz="0" izz="0.01"/>
    </inertial>
  </link>

  <joint name="cargo_platform_joint" type="fixed">
    <parent link="base_link"/>
    <child link="cargo_platform"/>
  </joint>

  <!-- ==================== 激光雷达 ==================== -->
  <link name="laser_frame">
    <visual>
      <geometry>
        <cylinder radius="0.03" length="0.02"/>
      </geometry>
      <origin xyz="0 0 0.01"/>
      <material name="red"/>
    </visual>
    <collision>
      <geometry>
        <cylinder radius="0.03" length="0.02"/>
      </geometry>
      <origin xyz="0 0 0.01"/>
    </collision>
    <inertial>
      <mass value="0.1"/>
      <inertia ixx="0.0001" ixy="0" ixz="0" iyy="0.0001" iyz="0" izz="0.0001"/>
    </inertial>
  </link>

  <joint name="laser_joint" type="fixed">
    <parent link="base_link"/>
    <child link="laser_frame"/>
    <origin xyz="0.15 0 0.12"/>
  </joint>

  <!-- ==================== Gazebo插件 ==================== -->

  <!-- 差分驱动插件 -->
  <gazebo>
    <plugin name="differential_drive" filename="libgazebo_ros_diff_drive.so">
      <ros>
        <namespace>$(arg agv_id)</namespace>
      </ros>
      <update_rate>50</update_rate>
      <left_joint>left_wheel_joint</left_joint>
      <right_joint>right_wheel_joint</right_joint>
      <wheel_separation>0.34</wheel_separation>
      <wheel_diameter>0.1</wheel_diameter>
      <max_wheel_torque>20</max_wheel_torque>
      <max_wheel_acceleration>1.0</max_wheel_acceleration>
      <publish_odom>true</publish_odom>
      <publish_odom_tf>true</publish_odom_tf>
      <publish_wheel_tf>true</publish_wheel_tf>
      <odometry_frame>odom</odometry_frame>
      <robot_base_frame>base_link</robot_base_frame>
    </plugin>
  </gazebo>

  <!-- 激光雷达插件 -->
  <gazebo reference="laser_frame">
    <sensor type="gpu_lidar" name="laser">
      <always_on>true</always_on>
      <update_rate>10</update_rate>
      <visualize>true</visualize>
      <lidar>
        <scan>
          <horizontal>
            <samples>360</samples>
            <resolution>1</resolution>
            <min_angle>-3.14159</min_angle>
            <max_angle>3.14159</max_angle>
          </horizontal>
        </scan>
        <range>
          <min>0.1</min>
          <max>10.0</max>
          <resolution>0.01</resolution>
        </range>
        <noise>
          <type>gaussian</type>
          <mean>0.0</mean>
          <stddev>0.01</stddev>
        </noise>
      </lidar>
      <plugin name="laser_plugin" filename="libgazebo_ros_laser.so">
        <ros>
          <namespace>$(arg agv_id)</namespace>
        </ros>
        <frame_name>laser_frame</frame_name>
      </plugin>
    </sensor>
  </gazebo>

  <!-- IMU插件 -->
  <gazebo>
    <plugin name="imu_plugin" filename="libgazebo_ros_imu_sensor.so">
      <ros>
        <namespace>$(arg agv_id)</namespace>
      </ros>
      <body_name>base_link</body_name>
      <frame_name>base_link</frame_name>
      <update_rate>50</update_rate>
    </plugin>
  </gazebo>

  <!-- Gazebo材质 -->
  <gazebo reference="base_link">
    <material>Gazebo/Gray</material>
  </gazebo>
  <gazebo reference="left_wheel">
    <material>Gazebo/DarkGrey</material>
  </gazebo>
  <gazebo reference="right_wheel">
    <material>Gazebo/DarkGrey</material>
  </gazebo>
  <gazebo reference="cargo_platform">
    <material>Gazebo/White</material>
  </gazebo>
  <gazebo reference="laser_frame">
    <material>Gazebo/Red</material>
  </gazebo>

</robot>
